Workbook

Sheet README
A1: Reporte Vitalbit - Dashboard Ejecutivo (Cliente)
A3: Definiciones clave:
A4: • Total RAW: todos los registros consolidados desde DESGLOSE ACSVD (sin recortes).
A5: • Muestra aplicable: denominador dinámico según la condición seleccionada (solo registros con ese dato disponible).
A6: • Prediabetes: incluye GAA o glucosa 100–125 mg/dL (cuando solo hay valor numérico).
A7: • HTA vs Pre-HTA: se reportan por separado; Pre-HTA NO se cuenta como HTA.
A8: • Dislipidemia: usa columna explícita si existe; si falta, regla >200 usando CT (o columnas equivalentes).
A10: Cómo usar:
A11: 1) Abre pestaña ORIFLAME o KIO.
A12: 2) Ajusta filtros (Sexo, Edad, Condición, Jornada y Población en KIO).
A13: 3) KPIs y gráficas se actualizan automáticamente.
A15: Trazabilidad:
A16: • Revisa DATA_QUALITY y DIC_DISLIPIDEMIA para ver cobertura por archivo y reglas aplicadas.

Sheet BASE_MODELADA
A1: Cliente | B1: Fuente | C1: Jornada | D1: Poblacion | E1: Empresa_raw | F1: Nombre | G1: Edad | H1: Sexo | I1: Rango_Edad | J1: DM_Cat | K1: Diabetes_Flag | L1: Prediabetes_Flag | M1: DM_Aplicable | N1: HTA_Cat | O1: HTA_Flag | P1: PreHTA_Flag | Q1: HTA_Aplicable | R1: IMC_Cat | S1: Sobrepeso_Flag | T1: Obesidad_Flag | U1: IMC_Aplicable | V1: Tabaquismo | W1: Fumador_Flag | X1: Tabaq_Aplicable | Y1: Dislipidemia | Z1: Disli_Flag | AA1: Disli_Aplicable | AB1: Disli_Fuente | AC1: Inscripcion | AD1: Cuestionario | AE1: Tiene_Labs | AF1: Demo_Valido
A2: ORIFLAME | B2: Oriflame | D2: ORIFLAME | F2: MICHELLE ALAN VÁZQUEZ LUNA | G2: 32 | H2: MASCULINO | I2: 26-35 | J2: NORMAL | K2: 0 | L2: 0 | M2: 1 | N2: NORMAL | O2: 0 | P2: 0 | Q2: 1 | R2: NORMOPESO | S2: 0 | T2: 0 | U2: 1 | V2: SI | W2: 1 | X2: 1 | Y2: NO | Z2: 0 | AA2: 1 | AB2: EXPL | AE2: 0 | AF2: 1
A3: ORIFLAME | B3: Oriflame | D3: ORIFLAME | F3: SAMANTA ABIGAIL RAMIREZ SANDOVAL | G3: 30 | H3: FEMENINO | I3: 26-35 | J3: NORMAL | K3: 0 | L3: 0 | M3: 1 | N3: NORMAL | O3: 0 | P3: 0 | Q3: 1 | R3: NORMOPESO | S3: 0 | T3: 0 | U3: 1 | V3: NO | W3: 0 | X3: 1 | Y3: NO | Z3: 0 | AA3: 1 | AB3: EXPL | AE3: 0 | AF3: 1
A4: ORIFLAME | B4: Oriflame | D4: ORIFLAME | F4: NURIA ITZEL FERREYRA ROMERO | G4: 31 | H4: FEMENINO | I4: 26-35 | J4: NORMAL | K4: 0 | L4: 0 | M4: 1 | N4: NORMAL | O4: 0 | P4: 0 | Q4: 1 | R4: NORMOPESO | S4: 0 | T4: 0 | U4: 1 | V4: NO | W4: 0 | X4: 1 | Y4: SI | Z4: 1 | AA4: 1 | AB4: EXPL | AE4: 0 | AF4: 1
A5: ORIFLAME | B5: Oriflame | D5: ORIFLAME | F5: JUAN MANUEL LOPEZ RODRIGUEZ | G5: 33 | H5: MASCULINO | I5: 26-35 | J5: DIABETES | K5: 1 | L5: 0 | M5: 1 | N5: NORMAL | O5: 0 | P5: 0 | Q5: 1 | R5: OBESIDAD | S5: 0 | T5: 1 | U5: 1 | V5: NO | W5: 0 | X5: 1 | Y5: NO | Z5: 0 | AA5: 1 | AB5: EXPL | AE5: 0 | AF5: 1
A6: ORIFLAME | B6: Oriflame | D6: ORIFLAME | F6: FERNANDA CAROLINA MUÑIZ QUEZADA | G6: 26 | H6: FEMENINO | I6: 26-35 | J6: NORMAL | K6: 0 | L6: 0 | M6: 1 | N6: NORMAL | O6: 0 | P6: 0 | Q6: 1 | R6: SOBREPESO | S6: 1 | T6: 0 | U6: 1 | V6: NO | W6: 0 | X6: 1 | Y6: SI | Z6: 1 | AA6: 1 | AB6: EXPL | AE6: 0 | AF6: 1
A7: ORIFLAME | B7: Oriflame | D7: ORIFLAME | F7: MARIBEL COLÍN JIMÉNEZ | G7: 45 | H7: FEMENINO | I7: 36-45 | J7: DIABETES | K7: 1 | L7: 0 | M7: 1 | N7: PRE-HTA | O7: 0 | P7: 1 | Q7: 1 | R7: SOBREPESO | S7: 1 | T7: 0 | U7: 1 | V7: NO | W7: 0 | X7: 1 | Y7: SI | Z7: 1 | AA7: 1 | AB7: EXPL | AE7: 0 | AF7: 1
A8: ORIFLAME | B8: Oriflame | D8: ORIFLAME | F8: MÓNICA CATHERIN SALAZAR VELÁZQUEZ | G8: 25 | H8: FEMENINO | I8: 18-25 | J8: NORMAL | K8: 0 | L8: 0 | M8: 1 | N8: NORMAL | O8: 0 | P8: 0 | Q8: 1 | R8: SOBREPESO | S8: 1 | T8: 0 | U8: 1 | V8: NO | W8: 0 | X8: 1 | Y8: NO | Z8: 0 | AA8: 1 | AB8: EXPL | AE8: 0 | AF8: 1
A9: ORIFLAME | B9: Oriflame | D9: ORIFLAME | F9: ANGÉLICA MÁRQUEZ MARTÍNEZ | G9: 45 | H9: FEMENINO | I9: 36-45 | J9: DIABETES | K9: 1 | L9: 0 | M9: 1 | N9: PRE-HTA | O9: 0 | P9: 1 | Q9: 1 | R9: NORMOPESO | S9: 0 | T9: 0 | U9: 1 | V9: NO | W9: 0 | X9: 1 | Y9: SI | Z9: 1 | AA9: 1 | AB9: EXPL | AE9: 0 | AF9: 1
A10: ORIFLAME | B10: Oriflame | D10: ORIFLAME | F10: OSCAR MATUS GARCIA | G10: 52 | H10: MASCULINO | I10: 46-55 | J10: DIABETES | K10: 1 | L10: 0 | M10: 1 | N10: PRE-HTA | O10: 0 | P10: 1 | Q10: 1 | R10: SOBREPESO | S10: 1 | T10: 0 | U10: 1 | V10: SI | W10: 1 | X10: 1 | Y10: SI | Z10: 1 | AA10: 1 | AB10: EXPL | AE10: 0 | AF10: 1
A11: ORIFLAME | B11: Oriflame | D11: ORIFLAME | F11: SANDRA BELÉN GALICIA ESPINOZA | G11: 31 | H11: FEMENINO | I11: 26-35 | J11: NORMAL | K11: 0 | L11: 0 | M11: 1 | N11: NORMAL | O11: 0 | P11: 0 | Q11: 1 | R11: NORMOPESO | S11: 0 | T11: 0 | U11: 1 | V11: NO | W11: 0 | X11: 1 | Y11: NO | Z11: 0 | AA11: 1 | AB11: EXPL | AE11: 0 | AF11: 1
A12: ORIFLAME | B12: Oriflame | D12: ORIFLAME | F12: NANCY LUCERO MORENO VILLASEÑOR | G12: 28 | H12: FEMENINO | I12: 26-35 | J12: NORMAL | K12: 0 | L12: 0 | M12: 1 | N12: HTA | O12: 1 | P12: 0 | Q12: 1 | R12: NORMOPESO | S12: 0 | T12: 0 | U12: 1 | V12: SI | W12: 1 | X12: 1 | Y12: NO | Z12: 0 | AA12: 1 | AB12: EXPL | AE12: 0 | AF12: 1
A13: ORIFLAME | B13: Oriflame | D13: ORIFLAME | F13: PAULINA ISABEL PRIEGO QUEVEDO | G13: 37 | H13: FEMENINO | I13: 36-45 | J13: NORMAL | K13: 0 | L13: 0 | M13: 1 | N13: NORMAL | O13: 0 | P13: 0 | Q13: 1 | R13: NORMOPESO | S13: 0 | T13: 0 | U13: 1 | V13: SI | W13: 1 | X13: 1 | Y13: SI | Z13: 1 | AA13: 1 | AB13: EXPL | AE13: 0 | AF13: 1
... A28: ORIFLAME | B28: Oriflame | D28: ORIFLAME | F28: CARLOS OMAR DIAZ PIÑA | G28: 44 | H28: MASCULINO | I28: 36-45 | J28: NORMAL | K28: 0 | L28: 0 | M28: 1 | N28: PRE-HTA | O28: 0 | P28: 1 | Q28: 1 | R28: SOBREPESO | S28: 1 | T28: 0 | U28: 1 | V28: NO | W28: 0 | X28: 1 | Y28: SI | Z28: 1 | AA28: 1 | AB28: EXPL | AE28: 0 | AF28: 1
A29: ORIFLAME | B29: Oriflame | D29: ORIFLAME | I29: 56+ | K29: 0 | L29: 0 | M29: 0 | O29: 0 | P29: 0 | Q29: 0 | S29: 0 | T29: 0 | U29: 0 | W29: 0 | X29: 0 | Y29: NA | Z29: 0 | AA29: 0 | AB29: NA | AE29: 0 | AF29: 0
A30: ORIFLAME | B30: Oriflame | D30: ORIFLAME | I30: 56+ | K30: 0 | L30: 0 | M30: 0 | O30: 0 | P30: 0 | Q30: 0 | S30: 0 | T30: 0 | U30: 0 | W30: 0 | X30: 0 | Y30: NA | Z30: 0 | AA30: 0 | AB30: NA | AE30: 0 | AF30: 0
A31: KIO | B31: KIO 24 | C31: 2025-11-24 | D31: IT SERVICES | E31: IT | F31: Maria Azucena Sánchez Hernández | G31: 39 | H31: FEMENINO | I31: 36-45 | J31: NORMAL | K31: 0 | L31: 0 | M31: 1 | N31: PRE-HTA | O31: 0 | P31: 1 | Q31: 1 | R31: OBESIDAD | S31: 0 | T31: 1 | U31: 1 | V31: NO | W31: 0 | X31: 1 | Y31: NO | Z31: 0 | AA31: 1 | AB31: EXPL | AC31: OK | AD31: OK | AE31: 1 | AF31: 1
A32: KIO | B32: KIO 24 | C32: 2025-11-24 | D32: IT SERVICES | E32: IT | F32: Blanca Monica Perez Garcia | G32: 59 | H32: FEMENINO | I32: 56+ | J32: NORMAL | K32: 0 | L32: 0 | M32: 1 | N32: HTA | O32: 1 | P32: 0 | Q32: 1 | R32: OBESIDAD | S32: 0 | T32: 1 | U32: 1 | V32: NO | W32: 0 | X32: 1 | Y32: SI | Z32: 1 | AA32: 1 | AB32: EXPL | AC32: OK | AD32: OK | AE32: 1 | AF32: 1
A33: KIO | B33: KIO 24 | C33: 2025-11-24 | D33: IT SERVICES | E33: IT | F33: Rodrigo Galindo Mello | G33: 41 | H33: MASCULINO | I33: 36-45 | J33: NORMAL | K33: 0 | L33: 0 | M33: 1 | N33: HTA | O33: 1 | P33: 0 | Q33: 1 | R33: SOBREPESO | S33: 1 | T33: 0 | U33: 1 | V33: NO | W33: 0 | X33: 1 | Y33: SI | Z33: 1 | AA33: 1 | AB33: EXPL | AC33: OK | AD33: OK | AE33: 1 | AF33: 1
A34: KIO | B34: KIO 24 | C34: 2025-11-24 | D34: IT SERVICES | E34: IT | F34: Emma Cristina Alguera Villicaña | G34: 40 | H34: FEMENINO | I34: 36-45 | J34: NORMAL | K34: 0 | L34: 0 | M34: 1 | N34: NORMAL | O34: 0 | P34: 0 | Q34: 1 | R34: NORMOPESO | S34: 0 | T34: 0 | U34: 1 | V34: NO | W34: 0 | X34: 1 | Y34: NO | Z34: 0 | AA34: 1 | AB34: EXPL | AC34: OK | AD34: OK | AE34: 1 | AF34: 1
A35: KIO | B35: KIO 24 | C35: 2025-11-24 | D35: IT SERVICES | E35: IT | F35: Alejandra Felisa Molina Cañas | G35: 53 | H35: FEMENINO | I35: 46-55 | J35: NORMAL | K35: 0 | L35: 0 | M35: 1 | N35: PRE-HTA | O35: 0 | P35: 1 | Q35: 1 | R35: NORMOPESO | S35: 0 | T35: 0 | U35: 1 | V35: NO | W35: 0 | X35: 1 | Y35: NO | Z35: 0 | AA35: 1 | AB35: EXPL | AC35: OK | AD35: OK | AE35: 1 | AF35: 1
A36: KIO | B36: KIO 24 | C36: 2025-11-24 | D36: IT SERVICES | E36: IT | F36: Joaquin Antonio Rodriguez Rojas | G36: 54 | H36: MASCULINO | I36: 46-55 | J36: NORMAL | K36: 0 | L36: 0 | M36: 1 | N36: PRE-HTA | O36: 0 | P36: 1 | Q36: 1 | R36: OBESIDAD | S36: 0 | T36: 1 | U36: 1 | V36: NO | W36: 0 | X36: 1 | Y36: SI | Z36: 1 | AA36: 1 | AB36: EXPL | AC36: OK | AD36: OK | AE36: 1 | AF36: 1
A37: KIO | B37: KIO 24 | C37: 2025-11-24 | D37: IT SERVICES | E37: IT | F37: Ana Larisa Carmona Landeros | G37: 44 | H37: FEMENINO | I37: 36-45 | J37: NORMAL | K37: 0 | L37: 0 | M37: 1 | O37: 0 | P37: 0 | Q37: 0 | S37: 0 | T37: 0 | U37: 0 | V37: NO | W37: 0 | X37: 1 | Y37: SI | Z37: 1 | AA37: 1 | AB37: EXPL | AC37: OK | AD37: OK | AE37: 1 | AF37: 1
A38: KIO | B38: KIO 24 | C38: 2025-11-24 | D38: IT SERVICES | E38: IT | F38: Leopoldo Humberto Vidal Reyna | G38: 50 | H38: MASCULINO | I38: 46-55 | J38: NORMAL | K38: 0 | L38: 0 | M38: 1 | N38: PRE-HTA | O38: 0 | P38: 1 | Q38: 1 | R38: SOBREPESO | S38: 1 | T38: 0 | U38: 1 | V38: NO | W38: 0 | X38: 1 | Y38: SI | Z38: 1 | AA38: 1 | AB38: EXPL | AC38: OK | AD38: OK | AE38: 1 | AF38: 1
A39: KIO | B39: KIO 24 | C39: 2025-11-24 | D39: IT SERVICES | E39: IT | F39: Delia Debora Sanchez Palma | G39: 60 | H39: FEMENINO | I39: 56+ | J39: NORMAL | K39: 0 | L39: 0 | M39: 1 | N39: HTA | O39: 1 | P39: 0 | Q39: 1 | R39: SOBREPESO | S39: 1 | T39: 0 | U39: 1 | V39: SI | W39: 1 | X39: 1 | Y39: SI | Z39: 1 | AA39: 1 | AB39: EXPL | AC39: OK | AD39: OK | AE39: 1 | AF39: 1
A40: KIO | B40: KIO 24 | C40: 2025-11-24 | D40: IT SERVICES | E40: IT | F40: Mario Antonio Perez Hernandez | G40: 47 | H40: MASCULINO | I40: 46-55 | J40: NORMAL | K40: 0 | L40: 0 | M40: 1 | N40: PRE-HTA | O40: 0 | P40: 1 | Q40: 1 | R40: SOBREPESO | S40: 1 | T40: 0 | U40: 1 | V40: SI | W40: 1 | X40: 1 | Y40: NO | Z40: 0 | AA40: 1 | AB40: EXPL | AC40: OK | AD40: OK | AE40: 1 | AF40: 1
A41: KIO | B41: KIO 24 | C41: 2025-11-24 | D41: IT SERVICES | E41: IT | F41: Victor Andrés Mendoza Orozco | G41: 40 | H41: MASCULINO | I41: 36-45 | J41: NORMAL | K41: 0 | L41: 0 | M41: 1 | N41: PRE-HTA | O41: 0 | P41: 1 | Q41: 1 | R41: SOBREPESO | S41: 1 | T41: 0 | U41: 1 | V41: NO | W41: 0 | X41: 1 | Y41: SI | Z41: 1 | AA41: 1 | AB41: EXPL | AC41: OK | AD41: OK | AE41: 1 | AF41: 1
A42: KIO | B42: KIO 24 | C42: 2025-11-24 | D42: IT SERVICES | E42: IT | F42: Pablo Cesar Martinez Mejia | G42: 46 | H42: MASCULINO | I42: 46-55 | J42: NORMAL | K42: 0 | L42: 0 | M42: 1 | N42: PRE-HTA | O42: 0 | P42: 1 | Q42: 1 | R42: OBESIDAD | S42: 0 | T42: 1 | U42: 1 | V42: NO | W42: 0 | X42: 1 | Y42: SI | Z42: 1 | AA42: 1 | AB42: EXPL | AC42: OK | AD42: OK | AE42: 1 | AF42: 1
A43: KIO | B43: KIO 24 | C43: 2025-11-24 | D43: IT SERVICES | E43: IT | F43: Gabriel Villerias Fernandez | G43: 46 | H43: MASCULINO | I43: 46-55 | J43: NORMAL | K43: 0 | L43: 0 | M43: 1 | N43: PRE-HTA | O43: 0 | P43: 1 | Q43: 1 | R43: NORMOPESO | S43: 0 | T43: 0 | U43: 1 | V43: NO | W43: 0 | X43: 1 | Y43: SI | Z43: 1 | AA43: 1 | AB43: EXPL | AC43: OK | AD43: OK | AE43: 1 | AF43: 1
A44: KIO | B44: KIO 24 | C44: 2025-11-24 | D44: IT SERVICES | E44: IT | F44: Christian Alejandro Miguel Diaz | G44: 39 | H44: MASCULINO | I44: 36-45 | J44: NORMAL | K44: 0 | L44: 0 | M44: 1 | N44: NORMAL | O44: 0 | P44: 0 | Q44: 1 | R44: OBESIDAD | S44: 0 | T44: 1 | U44: 1 | V44: NO | W44: 0 | X44: 1 | Y44: NO | Z44: 0 | AA44: 1 | AB44: EXPL | AC44: OK | AD44: OK | AE44: 1 | AF44: 1
A45: KIO | B45: KIO 24 | C45: 2025-11-24 | D45: SIN CLASIFICAR | E45: ? | F45: Jesus Alfredo Hernández Moreno | G45: 43 | H45: MASCULINO | I45: 36-45 | J45: NORMAL | K45: 0 | L45: 0 | M45: 1 | N45: PRE-HTA | O45: 0 | P45: 1 | Q45: 1 | R45: OBESIDAD | S45: 0 | T45: 1 | U45: 1 | V45: SI | W45: 1 | X45: 1 | Y45: SI | Z45: 1 | AA45: 1 | AB45: EXPL | AC45: OK | AD45: OK | AE45: 1 | AF45: 1
A46: KIO | B46: KIO 24 | C46: 2025-11-24 | D46: IT SERVICES | E46: IT | F46: Maria Del Refugio Liliana Villa Diaz | G46: 48 | H46: FEMENINO | I46: 46-55 | J46: NORMAL | K46: 0 | L46: 0 | M46: 1 | N46: PRE-HTA | O46: 0 | P46: 1 | Q46: 1 | R46: OBESIDAD | S46: 0 | T46: 1 | U46: 1 | V46: NO | W46: 0 | X46: 1 | Y46: SI | Z46: 1 | AA46: 1 | AB46: EXPL | AC46: OK | AD46: OK | AE46: 1 | AF46: 1
A47: KIO | B47: KIO 24 | C47: 2025-11-24 | D47: IT SERVICES | E47: IT | F47: Oscar Urrutia Siordia | G47: 43 | H47: MASCULINO | I47: 36-45 | J47: NORMAL | K47: 0 | L47: 0 | M47: 1 | N47: PRE-HTA | O47: 0 | P47: 1 | Q47: 1 | R47: OBESIDAD | S47: 0 | T47: 1 | U47: 1 | V47: NO | W47: 0 | X47: 1 | Y47: NO | Z47: 0 | AA47: 1 | AB47: EXPL | AC47: OK | AD47: OK | AE47: 1 | AF47: 1
A48: KIO | B48: KIO 24 | C48: 2025-11-24 | D48: IT SERVICES | E48: IT | F48: Itzel Ariadna Septimo Govea | G48: 32 | H48: FEMENINO | I48: 26-35 | J48: NORMAL | K48: 0 | L48: 0 | M48: 1 | N48: PRE-HTA | O48: 0 | P48: 1 | Q48: 1 | R48: SOBREPESO | S48: 1 | T48: 0 | U48: 1 | V48: SI | W48: 1 | X48: 1 | Y48: NO | Z48: 0 | AA48: 1 | AB48: EXPL | AC48: OK | AD48: OK | AE48: 1 | AF48: 1
A49: KIO | B49: KIO 24 | C49: 2025-11-24 | D49: IT SERVICES | E49: IT | F49: Ana Laura Gutierrez Arellano | G49: 34 | H49: FEMENINO | I49: 26-35 | J49: NORMAL | K49: 0 | L49: 0 | M49: 1 | N49: NORMAL | O49: 0 | P49: 0 | Q49: 1 | R49: NORMOPESO | S49: 0 | T49: 0 | U49: 1 | V49: SI | W49: 1 | X49: 1 | Y49: SI | Z49: 1 | AA49: 1 | AB49: EXPL | AC49: OK | AD49: OK | AE49: 1 | AF49: 1
... A73: KIO | B73: KIO 24 | C73: 2025-11-24 | D73: IT SERVICES | E73: IT | F73: Hector Manuel Ocaña Sacramento | G73: 41 | H73: MASCULINO | I73: 36-45 | J73: PREDIABETES | K73: 0 | L73: 1 | M73: 1 | N73: HTA | O73: 1 | P73: 0 | Q73: 1 | R73: OBESIDAD | S73: 0 | T73: 1 | U73: 1 | V73: SI | W73: 1 | X73: 1 | Y73: NO | Z73: 0 | AA73: 1 | AB73: EXPL | AC73: OK | AD73: OK | AE73: 1 | AF73: 1
A74: KIO | B74: KIO 24 | C74: 2025-11-24 | D74: IT SERVICES | E74: IT | F74: Martha Lorena Werner Camarena | G74: 55 | H74: FEMENINO | I74: 46-55 | J74: NORMAL | K74: 0 | L74: 0 | M74: 1 | N74: PRE-HTA | O74: 0 | P74: 1 | Q74: 1 | S74: 0 | T74: 0 | U74: 0 | W74: 0 | X74: 0 | Y74: SI | Z74: 1 | AA74: 1 | AB74: EXPL | AC74: OK | AD74: PENDIENTE | AE74: 1 | AF74: 1
A75: KIO | B75: KIO 24 | C75: 2025-11-24 | D75: IT SERVICES | E75: IT | F75: Fernando Palacios Saavedra | G75: 51 | H75: MASCULINO | I75: 46-55 | J75: NORMAL | K75: 0 | L75: 0 | M75: 1 | N75: NORMAL | O75: 0 | P75: 0 | Q75: 1 | R75: SOBREPESO | S75: 1 | T75: 0 | U75: 1 | V75: SI | W75: 1 | X75: 1 | Y75: NO | Z75: 0 | AA75: 1 | AB75: EXPL | AC75: OK | AD75: OK | AE75: 1 | AF75: 1
A76: KIO | B76: KIO 24 | C76: 2025-11-24 | D76: SIN CLASIFICAR | E76: ? | F76: Gustavo Camacho Vazquez | G76: 42 | H76: MASCULINO | I76: 36-45 | J76: NORMAL | K76: 0 | L76: 0 | M76: 1 | N76: NORMAL | O76: 0 | P76: 0 | Q76: 1 | S76: 0 | T76: 0 | U76: 0 | V76: NO | W76: 0 | X76: 1 | Y76: NO | Z76: 0 | AA76: 1 | AB76: EXPL | AC76: OK | AD76: OK | AE76: 1 | AF76: 1
A77: KIO | B77: KIO 24 | C77: 2025-11-24 | D77: IT SERVICES | E77: IT | F77: Moises Salgado Hernandez | G77: 35 | H77: MASCULINO | I77: 26-35 | J77: PREDIABETES | K77: 0 | L77: 1 | M77: 1 | N77: HTA | O77: 1 | P77: 0 | Q77: 1 | R77: OBESIDAD | S77: 0 | T77: 1 | U77: 1 | V77: NO | W77: 0 | X77: 1 | Y77: SI | Z77: 1 | AA77: 1 | AB77: EXPL | AC77: OK | AD77: OK | AE77: 1 | AF77: 1
...

Sheet DATA_QUALITY
A1: Auditoría de Base / Cobertura por Archivo
A3: Cliente | B3: Fuente | C3: RAW | D3: Atendidos | E3: Inscritos_OK | F3: Cuestionario_OK | G3: Con_Labs | H3: DM_app | I3: HTA_app | J3: IMC_app | K3: Tabaq_app | L3: Disli_app
A4: KIO | B4: Foraneos | C4: 10 | D4: 10 | E4: 10 | F4: 10 | G4: 10 | H4: 10 | I4: 0 | J4: 10 | K4: 10 | L4: 10
A5: KIO | B5: KIO 24 | C5: 70 | D5: 65 | E5: 61 | F5: 61 | G5: 62 | H5: 61 | I5: 61 | J5: 58 | K5: 61 | L5: 62
A6: KIO | B6: Kio 2 dic | C6: 66 | D6: 62 | E6: 62 | F6: 56 | G6: 61 | H6: 61 | I6: 21 | J6: 60 | K6: 56 | L6: 61
A7: KIO | B7: Kio 25 | C7: 127 | D7: 119 | E7: 119 | F7: 118 | G7: 119 | H7: 119 | I7: 77 | J7: 117 | K7: 119 | L7: 119
A8: KIO | B8: Kio 26 | C8: 70 | D8: 63 | E8: 49 | F8: 60 | G8: 62 | H8: 62 | I8: 36 | J8: 62 | K8: 60 | L8: 62
A9: KIO | B9: Kio 27 | C9: 89 | D9: 81 | E9: 66 | F9: 74 | G9: 80 | H9: 80 | I9: 80 | J9: 80 | K9: 75 | L9: 80
A10: ORIFLAME | B10: Oriflame | C10: 29 | D10: 27 | E10: 0 | F10: 0 | G10: 0 | H10: 27 | I10: 27 | J10: 27 | K10: 27 | L10: 27
A20: Distribución Dislipidemia por fuente/regla
A22: Fuente | B22: Disli_Fuente | C22: N | D22: SI | E22: NO | F22: NA
A23: Foraneos | B23: CT_RULE | C23: 10 | D23: 6 | E23: 4 | F23: 0
A24: KIO 24 | B24: EXPL | C24: 61 | D24: 27 | E24: 34 | F24: 0
A25: KIO 24 | B25: JO_RULE | C25: 1 | D25: 0 | E25: 1 | F25: 0
A26: KIO 24 | B26: NA | C26: 8 | D26: 0 | E26: 0 | F26: 8
A27: Kio 2 dic | B27: CT_RULE | C27: 61 | D27: 27 | E27: 34 | F27: 0
A28: Kio 2 dic | B28: NA | C28: 5 | D28: 0 | E28: 0 | F28: 5
A29: Kio 25 | B29: EXPL | C29: 119 | D29: 56 | E29: 63 | F29: 0
A30: Kio 25 | B30: NA | C30: 8 | D30: 0 | E30: 0 | F30: 8
A31: Kio 26 | B31: EXPL | C31: 62 | D31: 44 | E31: 18 | F31: 0
A32: Kio 26 | B32: NA | C32: 8 | D32: 0 | E32: 0 | F32: 8
A33: Kio 27 | B33: CT_RULE | C33: 80 | D33: 42 | E33: 38 | F33: 0
A34: Kio 27 | B34: NA | C34: 9 | D34: 0 | E34: 0 | F34: 9
... A36: Oriflame | B36: NA | C36: 2 | D36: 0 | E36: 0 | F36: 2

Sheet METODOLOGÍA_CLÍNICA
B1: METODOLOGÍA CLÍNICA Y DEFINICIÓN DE UNIVERSOS
B4: 1) Universos de datos (para evitar incongruencias)
B5: • Universo operativo (Atendidos): registros que aparecen en la base operativa / jornada, aunque puedan tener campos clínicos incompletos. • Universo clínico (Muestra aplicable / screening completo): subconjunto de registros con los campos necesarios para el KPI o gráfica. Regla clave: los KPIs y porcentajes del dashboard se calculan siempre sobre la Muestra aplicable del indicador, NO sobre el total operativo, para evitar sesgos.
B7: 2) Elegibilidad del Riesgo CV (ASCVD)
B8: El score ASCVD a 10 años solo es clínicamente aplicable para ciertos rangos de edad y con biometría completa. Por eso, al filtrar por edades jóvenes o registros sin biometría suficiente, la 'Muestra aplicable' puede disminuir. En el dashboard, esto se refleja en el KPI de Muestra aplicable y en los porcentajes.
B10: 3) Reglas de clasificación usadas en el dashboard
B11: • IMC: Normal / Sobrepeso / Obesidad (I, II, III) según la categoría reportada. • Diabetes (DM): Normal / Prediabetes / Diabetes según la clasificación reportada. • Hipertensión (HAS/HTA): se consideran casos de enfermedad únicamente Hipertensión G1 y G2. - Prehipertensión se muestra como hallazgo preventivo (si aplica en el dataset) y NO se suma como diagnóstico de enfermedad en KPI principal. • Tabaquismo: Fumador actual = 'SI' (según respuesta de tabaquismo en base).
B13: 4) Duplicados y consistencia (principalmente KIO)
B14: En KIO existen registros repetidos entre jornadas/hojas. Para no inflar cifras: • Se conserva el universo RAW en las hojas de base. • Para KPIs, cuando hay duplicados, se prioriza el registro con mayor completitud clínica (más campos no vacíos). Esto evita que un mismo colaborador cuente dos veces en prevalencias.
B16: 5) Recomendación de lectura para ejecutivos
B17: Cuando se usa un filtro (Sexo / Edad / Condición / Jornada), revisar primero: • KPI 'Muestra aplicable' (denominador) • KPI 'Casos' (numerador) • KPI '% sobre muestra' (prevalencia) Así se garantiza que las comparaciones siempre sean sobre el mismo universo del indicador.
B19: Fuente: DESGLOSE ACSVD.xlsx (consolidado) y/o base modelada del reporte. Este documento NO altera datos, solo describe la metodología y definiciones usadas.

Sheet OPERATIVO
A1: Reporte Operativo (KIO) - Inscripción / Cuestionario / Tomas / Pendientes
A3: Jornada | B3: Poblacion | C3: Fuente | D3: RAW | E3: Inscritos | F3: Cuestionarios | G3: Con_Labs | H3: Pendientes_Insc | I3: Pendientes_Cuest | J3: Jornada | K3: Inscritos | L3: Cuestionarios | M3: Con_Labs
B4: DATA CENTERS | C4: Foraneos | D4: 10 | E4: 10 | F4: 10 | G4: 10 | H4: 0 | I4: 0 | K4: 10 | L4: 10 | M4: 10
A5: 2025-11-24 | B5: IT SERVICES | C5: KIO 24 | D5: 52 | E5: 51 | F5: 51 | G5: 52 | H5: 1 | I5: 1 | J5: 2025-11-24 | K5: 61 | L5: 61 | M5: 62
A6: 2025-11-24 | B6: SIN CLASIFICAR | C6: KIO 24 | D6: 18 | E6: 10 | F6: 10 | G6: 10 | H6: 0 | I6: 0 | J6: 2025-11-25 | K6: 119 | L6: 118 | M6: 119
A7: 2025-11-25 | B7: IT SERVICES | C7: Kio 25 | D7: 104 | E7: 104 | F7: 103 | G7: 104 | H7: 0 | I7: 1 | J7: 2025-11-26 | K7: 49 | L7: 60 | M7: 62
A8: 2025-11-25 | B8: SIN CLASIFICAR | C8: Kio 25 | D8: 23 | E8: 15 | F8: 15 | G8: 15 | H8: 0 | I8: 1 | J8: 2025-11-27 | K8: 66 | L8: 74 | M8: 80
A9: 2025-11-26 | B9: IT SERVICES | C9: Kio 26 | D9: 49 | E9: 36 | F9: 48 | G9: 49 | H9: 13 | I9: 1 | J9: 2025-12-02 | K9: 62 | L9: 56 | M9: 61
A10: 2025-11-26 | B10: SIN CLASIFICAR | C10: Kio 26 | D10: 21 | E10: 13 | F10: 12 | G10: 13 | H10: 0 | I10: 2
A11: 2025-11-27 | B11: DATA CENTERS | C11: Kio 27 | D11: 2 | E11: 2 | F11: 2 | G11: 2 | H11: 0 | I11: 0
A12: 2025-11-27 | B12: IT SERVICES | C12: Kio 27 | D12: 63 | E12: 49 | F12: 60 | G12: 63 | H12: 14 | I12: 2
A13: 2025-11-27 | B13: SIN CLASIFICAR | C13: Kio 27 | D13: 24 | E13: 15 | F13: 12 | G13: 15 | H13: 0 | I13: 4
A14: 2025-12-02 | B14: DATA CENTERS | C14: Kio 2 dic | D14: 60 | E14: 60 | F14: 54 | G14: 59 | H14: 0 | I14: 6
A15: 2025-12-02 | B15: SIN CLASIFICAR | C15: Kio 2 dic | D15: 6 | E15: 2 | F15: 2 | G15: 2 | H15: 0 | I15: 0

Sheet DIC_DISLIPIDEMIA
A1: Diccionario Dislipidemia: origen de cálculo por fuente
A3: Fuente | B3: Disli_Fuente | C3: N | D3: SI | E3: NO | F3: NA
A4: Foraneos | B4: CT_RULE | C4: 10 | D4: 6 | E4: 4 | F4: 0
A5: KIO 24 | B5: EXPL | C5: 61 | D5: 27 | E5: 34 | F5: 0
A6: KIO 24 | B6: JO_RULE | C6: 1 | D6: 0 | E6: 1 | F6: 0
A7: KIO 24 | B7: NA | C7: 8 | D7: 0 | E7: 0 | F7: 8
A8: Kio 2 dic | B8: CT_RULE | C8: 61 | D8: 27 | E8: 34 | F8: 0
A9: Kio 2 dic | B9: NA | C9: 5 | D9: 0 | E9: 0 | F9: 5
A10: Kio 25 | B10: EXPL | C10: 119 | D10: 56 | E10: 63 | F10: 0
A11: Kio 25 | B11: NA | C11: 8 | D11: 0 | E11: 0 | F11: 8
A12: Kio 26 | B12: EXPL | C12: 62 | D12: 44 | E12: 18 | F12: 0
A13: Kio 26 | B13: NA | C13: 8 | D13: 0 | E13: 0 | F13: 8
A14: Kio 27 | B14: CT_RULE | C14: 80 | D14: 42 | E14: 38 | F14: 0
A15: Kio 27 | B15: NA | C15: 9 | D15: 0 | E15: 0 | F15: 9
... A17: Oriflame | B17: NA | C17: 2 | D17: 0 | E17: 0 | F17: 2

Sheet ORIFLAME
A1: Reporte Vitalbit Ejecutivo Pro — ORIFLAME | 2026-01-08
A2: HALLAZGOS CLAVE: • Dashboard interactivo con filtros por sexo, edad, condición, jornada y población (KIO). • Prediabetes incluye GAA y glucosa 100–125 mg/dL; Diabetes ≥126 mg/dL o 'DM'. • HTA y Pre-HTA se reportan por separado (no se mezclan). • Sobrepeso y Obesidad se reportan por separado. • Dislipidemia: se usa columna explícita si existe; si falta, regla >200 (CT/J-O según disponibilidad).
A9: FILTROS (Interactivo)
A10: Sexo | B10: Todos | D10: Tip: cambia filtros y el dashboard se actualiza.
A11: Rango de Edad | B11: Todos
A12: Condición | B12: Diabetes
A13: Jornada/Fuente | B13: Todos
A14: Nota: Los KPIs y porcentajes se calculan exclusivamente sobre la 'Muestra aplicable' (registros con información clínica completa según el set de variables requerido por cada indicador). | K14: ⓘ BASE KPI
A15: RESUMEN (KPIs)
A16: Total RAW (registros) | D16: Muestra aplicable | G16: Casos (según condición) | I16: % sobre muestra
A17: =COUNTIFS(BASE_MODELADA!$A$2:$A$462,"ORIFLAME",BASE_MODELADA!$H$2:$H$462,IF($B$10="Todos","*",$B$10),BASE_MODELADA!$I$2:$I$462,IF($B$11="Todos","*",$B$11),BASE_MODELADA!$B$2:$B$462,IF($B$13="Todos","*",$B$13)) -> 27 | D17: =IF($B$12="Todos",COUNTIFS(BASE_MODELADA!$A$2:$A$462,"ORIFLAME",BASE_MODELADA!$H$2:$H$462,IF($B$10="Todos","*",$B$10),BASE_MODELADA!$I$2:$I$462,IF($B$11="Todos","*",$B$11),BASE_MODELADA!$B$2:$B$462,IF($B$13="Todos","*",$B$13),BASE_MODELADA!$AF$2:$AF$462,1),IF(OR($B$12="Diabetes",$B$12="Prediabetes"),COUNTIFS(BASE_MODELADA!$A$2:$A$462,"ORIFLAME",BASE_MODELADA!$H$2:$H$462,IF($B$10="Todos","*",$B$10),BASE_MODELADA!$I$2:$I$462,IF($B$11="Todos","*",$B$11),BASE_MODELADA!$B$2:$B$462,IF($B$13="Todos","*",$B$13),BASE_MODELADA!$M$2:$M$462,1),IF(OR($B$12="HTA",$B$12="Pre-HTA"),COUNTIFS(BASE_MODELADA!$A$2:$A$462,"ORIFLAME",BASE_MODELADA!$H$2:$H$462,IF($B$10="Todos","*",$B$10),BASE_MODELADA!$I$2:$I$462,IF($B$11="Todos","*",$B$11),BASE_MODELADA!$B$2:$B$462,IF($B$13="Todos","*",$B$13),BASE_MODELADA!$Q$2:$Q$462,1),IF(OR($B$12="Sobrepeso",$B$12="Obesidad"),COUNTIFS(BASE_MODELADA!$A$2:$A$462,"ORIFLAME",BASE_MODELADA!$H$2:$H$462,IF($B$10="Todos","*",$B$10),BASE_MODELADA!$I$2:$I$462,IF($B$11="Todos","*",$B$11),BASE_MODELADA!$B$2:$B$462,IF($B$13="Todos","*",$B$13),BASE_MODELADA!$U$2:$U$462,1),IF($B$12="Dislipidemia",COUNTIFS(BASE_MODELADA!$A$2:$A$462,"ORIFLAME",BASE_MODELADA!$H$2:$H$462,IF($B$10="Todos","*",$B$10),BASE_MODELADA!$I$2:$I$462,IF($B$11="Todos","*",$B$11),BASE_MODELADA!$B$2:$B$462,IF($B$13="Todos","*",$B$13),BASE_MODELADA!$AA$2:$AA$462,1),IF($B$12="Tabaquismo",COUNTIFS(BASE_MODELADA!$A$2:$A$462,"ORIFLAME",BASE_MODELADA!$H$2:$H$462,IF($B$10="Todos","*",$B$10),BASE_MODELADA!$I$2:$I$462,IF($B$11="Todos","*",$B$11),BASE_MODELADA!$B$2:$B$462,IF($B$13="Todos","*",$B$13),BASE_MODELADA!$X$2:$X$462,1),0)))))) -> 27 | G17: =IF($B$12="Diabetes",COUNTIFS(BASE_MODELADA!$A$2:$A$462,"ORIFLAME",BASE_MODELADA!$H$2:$H$462,IF($B$10="Todos","*",$B$10),BASE_MODELADA!$I$2:$I$462,IF($B$11="Todos","*",$B$11),BASE_MODELADA!$B$2:$B$462,IF($B$13="Todos","*",$B$13),BASE_MODELADA!$K$2:$K$462,1),IF($B$12="Prediabetes",COUNTIFS(BASE_MODELADA!$A$2:$A$462,"ORIFLAME",BASE_MODELADA!$H$2:$H$462,IF($B$10="Todos","*",$B$10),BASE_MODELADA!$I$2:$I$462,IF($B$11="Todos","*",$B$11),BASE_MODELADA!$B$2:$B$462,IF($B$13="Todos","*",$B$13),BASE_MODELADA!$L$2:$L$462,1),IF($B$12="HTA",COUNTIFS(BASE_MODELADA!$A$2:$A$462,"ORIFLAME",BASE_MODELADA!$H$2:$H$462,IF($B$10="Todos","*",$B$10),BASE_MODELADA!$I$2:$I$462,IF($B$11="Todos","*",$B$11),BASE_MODELADA!$B$2:$B$462,IF($B$13="Todos","*",$B$13),BASE_MODELADA!$O$2:$O$462,1),IF($B$12="Pre-HTA",COUNTIFS(BASE_MODELADA!$A$2:$A$462,"ORIFLAME",BASE_MODELADA!$H$2:$H$462,IF($B$10="Todos","*",$B$10),BASE_MODELADA!$I$2:$I$462,IF($B$11="Todos","*",$B$11),BASE_MODELADA!$B$2:$B$462,IF($B$13="Todos","*",$B$13),BASE_MODELADA!$P$2:$P$462,1),IF($B$12="Sobrepeso",COUNTIFS(BASE_MODELADA!$A$2:$A$462,"ORIFLAME",BASE_MODELADA!$H$2:$H$462,IF($B$10="Todos","*",$B$10),BASE_MODELADA!$I$2:$I$462,IF($B$11="Todos","*",$B$11),BASE_MODELADA!$B$2:$B$462,IF($B$13="Todos","*",$B$13),BASE_MODELADA!$S$2:$S$462,1),IF($B$12="Obesidad",COUNTIFS(BASE_MODELADA!$A$2:$A$462,"ORIFLAME",BASE_MODELADA!$H$2:$H$462,IF($B$10="Todos","*",$B$10),BASE_MODELADA!$I$2:$I$462,IF($B$11="Todos","*",$B$11),BASE_MODELADA!$B$2:$B$462,IF($B$13="Todos","*",$B$13),BASE_MODELADA!$T$2:$T$462,1),IF($B$12="Dislipidemia",COUNTIFS(BASE_MODELADA!$A$2:$A$462,"ORIFLAME",BASE_MODELADA!$H$2:$H$462,IF($B$10="Todos","*",$B$10),BASE_MODELADA!$I$2:$I$462,IF($B$11="Todos","*",$B$11),BASE_MODELADA!$B$2:$B$462,IF($B$13="Todos","*",$B$13),BASE_MODELADA!$Z$2:$Z$462,1),IF($B$12="Tabaquismo",COUNTIFS(BASE_MODELADA!$A$2:$A$462,"ORIFLAME",BASE_MODELADA!$H$2:$H$462,IF($B$10="Todos","*",$B$10),BASE_MODELADA!$I$2:$I$462,IF($B$11="Todos","*",$B$11),BASE_MODELADA!$B$2:$B$462,IF($B$13="Todos","*",$B$13),BASE_MODELADA!$W$2:$W$462,1),0)))))))) -> 8 | I17: =IFERROR($G$17/$D$17,0) -> 0.2962963
A20: Distribución Edad x Género (condición seleccionada)
A21: Rango Edad | B21: Femenino | C21: Masculino | D21: Total | E21: %
A22: 18-25 | B22: =IF($B$12="Todos",COUNTIFS(BASE_MODELADA!$A$2:$A$462,"ORIFLAME",BASE_MODELADA!$H$2:$H$462,IF($B$10="Todos","FEMENINO",$B$10),BASE_MODELADA!$I$2:$I$462,IF($B$11="Todos",$A22,$B$11),BASE_MODELADA!$B$2:$B$462,IF($B$13="Todos","*",$B$13),BASE_MODELADA!$AF$2:$AF$462,1),IF($B$12="Diabetes",COUNTIFS(BASE_MODELADA!$A$2:$A$462,"ORIFLAME",BASE_MODELADA!$H$2:$H$462,IF($B$10="Todos","FEMENINO",$B$10),BASE_MODELADA!$I$2:$I$462,IF($B$11="Todos",$A22,$B$11),BASE_MODELADA!$B$2:$B$462,IF($B$13="Todos","*",$B$13),BASE_MODELADA!$K$2:$K$462,1),IF($B$12="Prediabetes",COUNTIFS(BASE_MODELADA!$A$2:$A$462,"ORIFLAME",BASE_MODELADA!$H$2:$H$462,IF($B$10="Todos","FEMENINO",$B$10),BASE_MODELADA!$I$2:$I$462,IF($B$11="Todos",$A22,$B$11),BASE_MODELADA!$B$2:$B$462,IF($B$13="Todos","*",$B$13),BASE_MODELADA!$L$2:$L$462,1),IF($B$12="HTA",COUNTIFS(BASE_MODELADA!$A$2:$A$462,"ORIFLAME",BASE_MODELADA!$H$2:$H$462,IF($B$10="Todos","FEMENINO",$B$10),BASE_MODELADA!$I$2:$I$462,IF($B$11="Todos",$A22,$B$11),BASE_MODELADA!$B$2:$B$462,IF($B$13="Todos","*",$B$13),BASE_MODELADA!$O$2:$O$462,1),IF($B$12="Pre-HTA",COUNTIFS(BASE_MODELADA!$A$2:$A$462,"ORIFLAME",BASE_MODELADA!$H$2:$H$462,IF($B$10="Todos","FEMENINO",$B$10),BASE_MODELADA!$I$2:$I$462,IF($B$11="Todos",$A22,$B$11),BASE_MODELADA!$B$2:$B$462,IF($B$13="Todos","*",$B$13),BASE_MODELADA!$P$2:$P$462,1),IF($B$12="Sobrepeso",COUNTIFS(BASE_MODELADA!$A$2:$A$462,"ORIFLAME",BASE_MODELADA!$H$2:$H$462,IF($B$10="Todos","FEMENINO",$B$10),BASE_MODELADA!$I$2:$I$462,IF($B$11="Todos",$A22,$B$11),BASE_MODELADA!$B$2:$B$462,IF($B$13="Todos","*",$B$13),BASE_MODELADA!$S$2:$S$462,1),IF($B$12="Obesidad",COUNTIFS(BASE_MODELADA!$A$2:$A$462,"ORIFLAME",BASE_MODELADA!$H$2:$H$462,IF($B$10="Todos","FEMENINO",$B$10),BASE_MODELADA!$I$2:$I$462,IF($B$11="Todos",$A22,$B$11),BASE_MODELADA!$B$2:$B$462,IF($B$13="Todos","*",$B$13),BASE_MODELADA!$T$2:$T$462,1),IF($B$12="Dislipidemia",COUNTIFS(BASE_MODELADA!$A$2:$A$462,"ORIFLAME",BASE_MODELADA!$H$2:$H$462,IF($B$10="Todos","FEMENINO",$B$10),BASE_MODELADA!$I$2:$I$462,IF($B$11="Todos",$A22,$B$11),BASE_MODELADA!$B$2:$B$462,IF($B$13="Todos","*",$B$13),BASE_MODELADA!$Z$2:$Z$462,1),IF($B$12="Tabaquismo",COUNTIFS(BASE_MODELADA!$A$2:$A$462,"ORIFLAME",BASE_MODELADA!$H$2:$H$462,IF($B$10="Todos","FEMENINO",$B$10),BASE_MODELADA!$I$2:$I$462,IF($B$11="Todos",$A22,$B$11),BASE_MODELADA!$B$2:$B$462,IF($B$13="Todos","*",$B$13),BASE_MODELADA!$W$2:$W$462,1),0))))))))) -> 0 | C22: =IF($B$12="Todos",COUNTIFS(BASE_MODELADA!$A$2:$A$462,"ORIFLAME",BASE_MODELADA!$H$2:$H$462,IF($B$10="Todos","MASCULINO",$B$10),BASE_MODELADA!$I$2:$I$462,IF($B$11="Todos",$A22,$B$11),BASE_MODELADA!$B$2:$B$462,IF($B$13="Todos","*",$B$13),BASE_MODELADA!$AF$2:$AF$462,1),IF($B$12="Diabetes",COUNTIFS(BASE_MODELADA!$A$2:$A$462,"ORIFLAME",BASE_MODELADA!$H$2:$H$462,IF($B$10="Todos","MASCULINO",$B$10),BASE_MODELADA!$I$2:$I$462,IF($B$11="Todos",$A22,$B$11),BASE_MODELADA!$B$2:$B$462,IF($B$13="Todos","*",$B$13),BASE_MODELADA!$K$2:$K$462,1),IF($B$12="Prediabetes",COUNTIFS(BASE_MODELADA!$A$2:$A$462,"ORIFLAME",BASE_MODELADA!$H$2:$H$462,IF($B$10="Todos","MASCULINO",$B$10),BASE_MODELADA!$I$2:$I$462,IF($B$11="Todos",$A22,$B$11),BASE_MODELADA!$B$2:$B$462,IF($B$13="Todos","*",$B$13),BASE_MODELADA!$L$2:$L$462,1),IF($B$12="HTA",COUNTIFS(BASE_MODELADA!$A$2:$A$462,"ORIFLAME",BASE_MODELADA!$H$2:$H$462,IF($B$10="Todos","MASCULINO",$B$10),BASE_MODELADA!$I$2:$I$462,IF($B$11="Todos",$A22,$B$11),BASE_MODELADA!$B$2:$B$462,IF($B$13="Todos","*",$B$13),BASE_MODELADA!$O$2:$O$462,1),IF($B$12="Pre-HTA",COUNTIFS(BASE_MODELADA!$A$2:$A$462,"ORIFLAME",BASE_MODELADA!$H$2:$H$462,IF($B$10="Todos","MASCULINO",$B$10),BASE_MODELADA!$I$2:$I$462,IF($B$11="Todos",$A22,$B$11),BASE_MODELADA!$B$2:$B$462,IF($B$13="Todos","*",$B$13),BASE_MODELADA!$P$2:$P$462,1),IF($B$12="Sobrepeso",COUNTIFS(BASE_MODELADA!$A$2:$A$462,"ORIFLAME",BASE_MODELADA!$H$2:$H$462,IF($B$10="Todos","MASCULINO",$B$10),BASE_MODELADA!$I$2:$I$462,IF($B$11="Todos",$A22,$B$11),BASE_MODELADA!$B$2:$B$462,IF($B$13="Todos","*",$B$13),BASE_MODELADA!$S$2:$S$462,1),IF($B$12="Obesidad",COUNTIFS(BASE_MODELADA!$A$2:$A$462,"ORIFLAME",BASE_MODELADA!$H$2:$H$462,IF($B$10="Todos","MASCULINO",$B$10),BASE_MODELADA!$I$2:$I$462,IF($B$11="Todos",$A22,$B$11),BASE_MODELADA!$B$2:$B$462,IF($B$13="Todos","*",$B$13),BASE_MODELADA!$T$2:$T$462,1),IF($B$12="Dislipidemia",COUNTIFS(BASE_MODELADA!$A$2:$A$462,"ORIFLAME",BASE_MODELADA!$H$2:$H$462,IF($B$10="Todos","MASCULINO",$B$10),BASE_MODELADA!$I$2:$I$462,IF($B$11="Todos",$A22,$B$11),BASE_MODELADA!$B$2:$B$462,IF($B$13="Todos","*",$B$13),BASE_MODELADA!$Z$2:$Z$462,1),IF($B$12="Tabaquismo",COUNTIFS(BASE_MODELADA!$A$2:$A$462,"ORIFLAME",BASE_MODELADA!$H$2:$H$462,IF($B$10="Todos","MASCULINO",$B$10),BASE_MODELADA!$I$2:$I$462,IF($B$11="Todos",$A22,$B$11),BASE_MODELADA!$B$2:$B$462,IF($B$13="Todos","*",$B$13),BASE_MODELADA!$W$2:$W$462,1),0))))))))) -> 0 | D22: =B22+C22 -> 0 | E22: =IFERROR(D22/$D$17,0) -> 0
A23: 26-35 | B23: =IF($B$12="Todos",COUNTIFS(BASE_MODELADA!$A$2:$A$462,"ORIFLAME",BASE_MODELADA!$H$2:$H$462,IF($B$10="Todos","FEMENINO",$B$10),BASE_MODELADA!$I$2:$I$462,IF($B$11="Todos",$A23,$B$11),BASE_MODELADA!$B$2:$B$462,IF($B$13="Todos","*",$B$13),BASE_MODELADA!$AF$2:$AF$462,1),IF($B$12="Diabetes",COUNTIFS(BASE_MODELADA!$A$2:$A$462,"ORIFLAME",BASE_MODELADA!$H$2:$H$462,IF($B$10="Todos","FEMENINO",$B$10),BASE_MODELADA!$I$2:$I$462,IF($B$11="Todos",$A23,$B$11),BASE_MODELADA!$B$2:$B$462,IF($B$13="Todos","*",$B$13),BASE_MODELADA!$K$2:$K$462,1),IF($B$12="Prediabetes",COUNTIFS(BASE_MODELADA!$A$2:$A$462,"ORIFLAME",BASE_MODELADA!$H$2:$H$462,IF($B$10="Todos","FEMENINO",$B$10),BASE_MODELADA!$I$2:$I$462,IF($B$11="Todos",$A23,$B$11),BASE_MODELADA!$B$2:$B$462,IF($B$13="Todos","*",$B$13),BASE_MODELADA!$L$2:$L$462,1),IF($B$12="HTA",COUNTIFS(BASE_MODELADA!$A$2:$A$462,"ORIFLAME",BASE_MODELADA!$H$2:$H$462,IF($B$10="Todos","FEMENINO",$B$10),BASE_MODELADA!$I$2:$I$462,IF($B$11="Todos",$A23,$B$11),BASE_MODELADA!$B$2:$B$462,IF($B$13="Todos","*",$B$13),BASE_MODELADA!$O$2:$O$462,1),IF($B$12="Pre-HTA",COUNTIFS(BASE_MODELADA!$A$2:$A$462,"ORIFLAME",BASE_MODELADA!$H$2:$H$462,IF($B$10="Todos","FEMENINO",$B$10),BASE_MODELADA!$I$2:$I$462,IF($B$11="Todos",$A23,$B$11),BASE_MODELADA!$B$2:$B$462,IF($B$13="Todos","*",$B$13),BASE_MODELADA!$P$2:$P$462,1),IF($B$12="Sobrepeso",COUNTIFS(BASE_MODELADA!$A$2:$A$462,"ORIFLAME",BASE_MODELADA!$H$2:$H$462,IF($B$10="Todos","FEMENINO",$B$10),BASE_MODELADA!$I$2:$I$462,IF($B$11="Todos",$A23,$B$11),BASE_MODELADA!$B$2:$B$462,IF($B$13="Todos","*",$B$13),BASE_MODELADA!$S$2:$S$462,1),IF($B$12="Obesidad",COUNTIFS(BASE_MODELADA!$A$2:$A$462,"ORIFLAME",BASE_MODELADA!$H$2:$H$462,IF($B$10="Todos","FEMENINO",$B$10),BASE_MODELADA!$I$2:$I$462,IF($B$11="Todos",$A23,$B$11),BASE_MODELADA!$B$2:$B$462,IF($B$13="Todos","*",$B$13),BASE_MODELADA!$T$2:$T$462,1),IF($B$12="Dislipidemia",COUNTIFS(BASE_MODELADA!$A$2:$A$462,"ORIFLAME",BASE_MODELADA!$H$2:$H$462,IF($B$10="Todos","FEMENINO",$B$10),BASE_MODELADA!$I$2:$I$462,IF($B$11="Todos",$A23,$B$11),BASE_MODELADA!$B$2:$B$462,IF($B$13="Todos","*",$B$13),BASE_MODELADA!$Z$2:$Z$462,1),IF($B$12="Tabaquismo",COUNTIFS(BASE_MODELADA!$A$2:$A$462,"ORIFLAME",BASE_MODELADA!$H$2:$H$462,IF($B$10="Todos","FEMENINO",$B$10),BASE_MODELADA!$I$2:$I$462,IF($B$11="Todos",$A23,$B$11),BASE_MODELADA!$B$2:$B$462,IF($B$13="Todos","*",$B$13),BASE_MODELADA!$W$2:$W$462,1),0))))))))) -> 0 | C23: =IF($B$12="Todos",COUNTIFS(BASE_MODELADA!$A$2:$A$462,"ORIFLAME",BASE_MODELADA!$H$2:$H$462,IF($B$10="Todos","MASCULINO",$B$10),BASE_MODELADA!$I$2:$I$462,IF($B$11="Todos",$A23,$B$11),BASE_MODELADA!$B$2:$B$462,IF($B$13="Todos","*",$B$13),BASE_MODELADA!$AF$2:$AF$462,1),IF($B$12="Diabetes",COUNTIFS(BASE_MODELADA!$A$2:$A$462,"ORIFLAME",BASE_MODELADA!$H$2:$H$462,IF($B$10="Todos","MASCULINO",$B$10),BASE_MODELADA!$I$2:$I$462,IF($B$11="Todos",$A23,$B$11),BASE_MODELADA!$B$2:$B$462,IF($B$13="Todos","*",$B$13),BASE_MODELADA!$K$2:$K$462,1),IF($B$12="Prediabetes",COUNTIFS(BASE_MODELADA!$A$2:$A$462,"ORIFLAME",BASE_MODELADA!$H$2:$H$462,IF($B$10="Todos","MASCULINO",$B$10),BASE_MODELADA!$I$2:$I$462,IF($B$11="Todos",$A23,$B$11),BASE_MODELADA!$B$2:$B$462,IF($B$13="Todos","*",$B$13),BASE_MODELADA!$L$2:$L$462,1),IF($B$12="HTA",COUNTIFS(BASE_MODELADA!$A$2:$A$462,"ORIFLAME",BASE_MODELADA!$H$2:$H$462,IF($B$10="Todos","MASCULINO",$B$10),BASE_MODELADA!$I$2:$I$462,IF($B$11="Todos",$A23,$B$11),BASE_MODELADA!$B$2:$B$462,IF($B$13="Todos","*",$B$13),BASE_MODELADA!$O$2:$O$462,1),IF($B$12="Pre-HTA",COUNTIFS(BASE_MODELADA!$A$2:$A$462,"ORIFLAME",BASE_MODELADA!$H$2:$H$462,IF($B$10="Todos","MASCULINO",$B$10),BASE_MODELADA!$I$2:$I$462,IF($B$11="Todos",$A23,$B$11),BASE_MODELADA!$B$2:$B$462,IF($B$13="Todos","*",$B$13),BASE_MODELADA!$P$2:$P$462,1),IF($B$12="Sobrepeso",COUNTIFS(BASE_MODELADA!$A$2:$A$462,"ORIFLAME",BASE_MODELADA!$H$2:$H$462,IF($B$10="Todos","MASCULINO",$B$10),BASE_MODELADA!$I$2:$I$462,IF($B$11="Todos",$A23,$B$11),BASE_MODELADA!$B$2:$B$462,IF($B$13="Todos","*",$B$13),BASE_MODELADA!$S$2:$S$462,1),IF($B$12="Obesidad",COUNTIFS(BASE_MODELADA!$A$2:$A$462,"ORIFLAME",BASE_MODELADA!$H$2:$H$462,IF($B$10="Todos","MASCULINO",$B$10),BASE_MODELADA!$I$2:$I$462,IF($B$11="Todos",$A23,$B$11),BASE_MODELADA!$B$2:$B$462,IF($B$13="Todos","*",$B$13),BASE_MODELADA!$T$2:$T$462,1),IF($B$12="Dislipidemia",COUNTIFS(BASE_MODELADA!$A$2:$A$462,"ORIFLAME",BASE_MODELADA!$H$2:$H$462,IF($B$10="Todos","MASCULINO",$B$10),BASE_MODELADA!$I$2:$I$462,IF($B$11="Todos",$A23,$B$11),BASE_MODELADA!$B$2:$B$462,IF($B$13="Todos","*",$B$13),BASE_MODELADA!$Z$2:$Z$462,1),IF($B$12="Tabaquismo",COUNTIFS(BASE_MODELADA!$A$2:$A$462,"ORIFLAME",BASE_MODELADA!$H$2:$H$462,IF($B$10="Todos","MASCULINO",$B$10),BASE_MODELADA!$I$2:$I$462,IF($B$11="Todos",$A23,$B$11),BASE_MODELADA!$B$2:$B$462,IF($B$13="Todos","*",$B$13),BASE_MODELADA!$W$2:$W$462,1),0))))))))) -> 1 | D23: =B23+C23 -> 1 | E23: =IFERROR(D23/$D$17,0) -> 0.037037037
A24: 36-45 | B24: =IF($B$12="Todos",COUNTIFS(BASE_MODELADA!$A$2:$A$462,"ORIFLAME",BASE_MODELADA!$H$2:$H$462,IF($B$10="Todos","FEMENINO",$B$10),BASE_MODELADA!$I$2:$I$462,IF($B$11="Todos",$A24,$B$11),BASE_MODELADA!$B$2:$B$462,IF($B$13="Todos","*",$B$13),BASE_MODELADA!$AF$2:$AF$462,1),IF($B$12="Diabetes",COUNTIFS(BASE_MODELADA!$A$2:$A$462,"ORIFLAME",BASE_MODELADA!$H$2:$H$462,IF($B$10="Todos","FEMENINO",$B$10),BASE_MODELADA!$I$2:$I$462,IF($B$11="Todos",$A24,$B$11),BASE_MODELADA!$B$2:$B$462,IF($B$13="Todos","*",$B$13),BASE_MODELADA!$K$2:$K$462,1),IF($B$12="Prediabetes",COUNTIFS(BASE_MODELADA!$A$2:$A$462,"ORIFLAME",BASE_MODELADA!$H$2:$H$462,IF($B$10="Todos","FEMENINO",$B$10),BASE_MODELADA!$I$2:$I$462,IF($B$11="Todos",$A24,$B$11),BASE_MODELADA!$B$2:$B$462,IF($B$13="Todos","*",$B$13),BASE_MODELADA!$L$2:$L$462,1),IF($B$12="HTA",COUNTIFS(BASE_MODELADA!$A$2:$A$462,"ORIFLAME",BASE_MODELADA!$H$2:$H$462,IF($B$10="Todos","FEMENINO",$B$10),BASE_MODELADA!$I$2:$I$462,IF($B$11="Todos",$A24,$B$11),BASE_MODELADA!$B$2:$B$462,IF($B$13="Todos","*",$B$13),BASE_MODELADA!$O$2:$O$462,1),IF($B$12="Pre-HTA",COUNTIFS(BASE_MODELADA!$A$2:$A$462,"ORIFLAME",BASE_MODELADA!$H$2:$H$462,IF($B$10="Todos","FEMENINO",$B$10),BASE_MODELADA!$I$2:$I$462,IF($B$11="Todos",$A24,$B$11),BASE_MODELADA!$B$2:$B$462,IF($B$13="Todos","*",$B$13),BASE_MODELADA!$P$2:$P$462,1),IF($B$12="Sobrepeso",COUNTIFS(BASE_MODELADA!$A$2:$A$462,"ORIFLAME",BASE_MODELADA!$H$2:$H$462,IF($B$10="Todos","FEMENINO",$B$10),BASE_MODELADA!$I$2:$I$462,IF($B$11="Todos",$A24,$B$11),BASE_MODELADA!$B$2:$B$462,IF($B$13="Todos","*",$B$13),BASE_MODELADA!$S$2:$S$462,1),IF($B$12="Obesidad",COUNTIFS(BASE_MODELADA!$A$2:$A$462,"ORIFLAME",BASE_MODELADA!$H$2:$H$462,IF($B$10="Todos","FEMENINO",$B$10),BASE_MODELADA!$I$2:$I$462,IF($B$11="Todos",$A24,$B$11),BASE_MODELADA!$B$2:$B$462,IF($B$13="Todos","*",$B$13),BASE_MODELADA!$T$2:$T$462,1),IF($B$12="Dislipidemia",COUNTIFS(BASE_MODELADA!$A$2:$A$462,"ORIFLAME",BASE_MODELADA!$H$2:$H$462,IF($B$10="Todos","FEMENINO",$B$10),BASE_MODELADA!$I$2:$I$462,IF($B$11="Todos",$A24,$B$11),BASE_MODELADA!$B$2:$B$462,IF($B$13="Todos","*",$B$13),BASE_MODELADA!$Z$2:$Z$462,1),IF($B$12="Tabaquismo",COUNTIFS(BASE_MODELADA!$A$2:$A$462,"ORIFLAME",BASE_MODELADA!$H$2:$H$462,IF($B$10="Todos","FEMENINO",$B$10),BASE_MODELADA!$I$2:$I$462,IF($B$11="Todos",$A24,$B$11),BASE_MODELADA!$B$2:$B$462,IF($B$13="Todos","*",$B$13),BASE_MODELADA!$W$2:$W$462,1),0))))))))) -> 2 | C24: =IF($B$12="Todos",COUNTIFS(BASE_MODELADA!$A$2:$A$462,"ORIFLAME",BASE_MODELADA!$H$2:$H$462,IF($B$10="Todos","MASCULINO",$B$10),BASE_MODELADA!$I$2:$I$462,IF($B$11="Todos",$A24,$B$11),BASE_MODELADA!$B$2:$B$462,IF($B$13="Todos","*",$B$13),BASE_MODELADA!$AF$2:$AF$462,1),IF($B$12="Diabetes",COUNTIFS(BASE_MODELADA!$A$2:$A$462,"ORIFLAME",BASE_MODELADA!$H$2:$H$462,IF($B$10="Todos","MASCULINO",$B$10),BASE_MODELADA!$I$2:$I$462,IF($B$11="Todos",$A24,$B$11),BASE_MODELADA!$B$2:$B$462,IF($B$13="Todos","*",$B$13),BASE_MODELADA!$K$2:$K$462,1),IF($B$12="Prediabetes",COUNTIFS(BASE_MODELADA!$A$2:$A$462,"ORIFLAME",BASE_MODELADA!$H$2:$H$462,IF($B$10="Todos","MASCULINO",$B$10),BASE_MODELADA!$I$2:$I$462,IF($B$11="Todos",$A24,$B$11),BASE_MODELADA!$B$2:$B$462,IF($B$13="Todos","*",$B$13),BASE_MODELADA!$L$2:$L$462,1),IF($B$12="HTA",COUNTIFS(BASE_MODELADA!$A$2:$A$462,"ORIFLAME",BASE_MODELADA!$H$2:$H$462,IF($B$10="Todos","MASCULINO",$B$10),BASE_MODELADA!$I$2:$I$462,IF($B$11="Todos",$A24,$B$11),BASE_MODELADA!$B$2:$B$462,IF($B$13="Todos","*",$B$13),BASE_MODELADA!$O$2:$O$462,1),IF($B$12="Pre-HTA",COUNTIFS(BASE_MODELADA!$A$2:$A$462,"ORIFLAME",BASE_MODELADA!$H$2:$H$462,IF($B$10="Todos","MASCULINO",$B$10),BASE_MODELADA!$I$2:$I$462,IF($B$11="Todos",$A24,$B$11),BASE_MODELADA!$B$2:$B$462,IF($B$13="Todos","*",$B$13),BASE_MODELADA!$P$2:$P$462,1),IF($B$12="Sobrepeso",COUNTIFS(BASE_MODELADA!$A$2:$A$462,"ORIFLAME",BASE_MODELADA!$H$2:$H$462,IF($B$10="Todos","MASCULINO",$B$10),BASE_MODELADA!$I$2:$I$462,IF($B$11="Todos",$A24,$B$11),BASE_MODELADA!$B$2:$B$462,IF($B$13="Todos","*",$B$13),BASE_MODELADA!$S$2:$S$462,1),IF($B$12="Obesidad",COUNTIFS(BASE_MODELADA!$A$2:$A$462,"ORIFLAME",BASE_MODELADA!$H$2:$H$462,IF($B$10="Todos","MASCULINO",$B$10),BASE_MODELADA!$I$2:$I$462,IF($B$11="Todos",$A24,$B$11),BASE_MODELADA!$B$2:$B$462,IF($B$13="Todos","*",$B$13),BASE_MODELADA!$T$2:$T$462,1),IF($B$12="Dislipidemia",COUNTIFS(BASE_MODELADA!$A$2:$A$462,"ORIFLAME",BASE_MODELADA!$H$2:$H$462,IF($B$10="Todos","MASCULINO",$B$10),BASE_MODELADA!$I$2:$I$462,IF($B$11="Todos",$A24,$B$11),BASE_MODELADA!$B$2:$B$462,IF($B$13="Todos","*",$B$13),BASE_MODELADA!$Z$2:$Z$462,1),IF($B$12="Tabaquismo",COUNTIFS(BASE_MODELADA!$A$2:$A$462,"ORIFLAME",BASE_MODELADA!$H$2:$H$462,IF($B$10="Todos","MASCULINO",$B$10),BASE_MODELADA!$I$2:$I$462,IF($B$11="Todos",$A24,$B$11),BASE_MODELADA!$B$2:$B$462,IF($B$13="Todos","*",$B$13),BASE_MODELADA!$W$2:$W$462,1),0))))))))) -> 1 | D24: =B24+C24 -> 3 | E24: =IFERROR(D24/$D$17,0) -> 0.11111111
A25: 46-55 | B25: =IF($B$12="Todos",COUNTIFS(BASE_MODELADA!$A$2:$A$462,"ORIFLAME",BASE_MODELADA!$H$2:$H$462,IF($B$10="Todos","FEMENINO",$B$10),BASE_MODELADA!$I$2:$I$462,IF($B$11="Todos",$A25,$B$11),BASE_MODELADA!$B$2:$B$462,IF($B$13="Todos","*",$B$13),BASE_MODELADA!$AF$2:$AF$462,1),IF($B$12="Diabetes",COUNTIFS(BASE_MODELADA!$A$2:$A$462,"ORIFLAME",BASE_MODELADA!$H$2:$H$462,IF($B$10="Todos","FEMENINO",$B$10),BASE_MODELADA!$I$2:$I$462,IF($B$11="Todos",$A25,$B$11),BASE_MODELADA!$B$2:$B$462,IF($B$13="Todos","*",$B$13),BASE_MODELADA!$K$2:$K$462,1),IF($B$12="Prediabetes",COUNTIFS(BASE_MODELADA!$A$2:$A$462,"ORIFLAME",BASE_MODELADA!$H$2:$H$462,IF($B$10="Todos","FEMENINO",$B$10),BASE_MODELADA!$I$2:$I$462,IF($B$11="Todos",$A25,$B$11),BASE_MODELADA!$B$2:$B$462,IF($B$13="Todos","*",$B$13),BASE_MODELADA!$L$2:$L$462,1),IF($B$12="HTA",COUNTIFS(BASE_MODELADA!$A$2:$A$462,"ORIFLAME",BASE_MODELADA!$H$2:$H$462,IF($B$10="Todos","FEMENINO",$B$10),BASE_MODELADA!$I$2:$I$462,IF($B$11="Todos",$A25,$B$11),BASE_MODELADA!$B$2:$B$462,IF($B$13="Todos","*",$B$13),BASE_MODELADA!$O$2:$O$462,1),IF($B$12="Pre-HTA",COUNTIFS(BASE_MODELADA!$A$2:$A$462,"ORIFLAME",BASE_MODELADA!$H$2:$H$462,IF($B$10="Todos","FEMENINO",$B$10),BASE_MODELADA!$I$2:$I$462,IF($B$11="Todos",$A25,$B$11),BASE_MODELADA!$B$2:$B$462,IF($B$13="Todos","*",$B$13),BASE_MODELADA!$P$2:$P$462,1),IF($B$12="Sobrepeso",COUNTIFS(BASE_MODELADA!$A$2:$A$462,"ORIFLAME",BASE_MODELADA!$H$2:$H$462,IF($B$10="Todos","FEMENINO",$B$10),BASE_MODELADA!$I$2:$I$462,IF($B$11="Todos",$A25,$B$11),BASE_MODELADA!$B$2:$B$462,IF($B$13="Todos","*",$B$13),BASE_MODELADA!$S$2:$S$462,1),IF($B$12="Obesidad",COUNTIFS(BASE_MODELADA!$A$2:$A$462,"ORIFLAME",BASE_MODELADA!$H$2:$H$462,IF($B$10="Todos","FEMENINO",$B$10),BASE_MODELADA!$I$2:$I$462,IF($B$11="Todos",$A25,$B$11),BASE_MODELADA!$B$2:$B$462,IF($B$13="Todos","*",$B$13),BASE_MODELADA!$T$2:$T$462,1),IF($B$12="Dislipidemia",COUNTIFS(BASE_MODELADA!$A$2:$A$462,"ORIFLAME",BASE_MODELADA!$H$2:$H$462,IF($B$10="Todos","FEMENINO",$B$10),BASE_MODELADA!$I$2:$I$462,IF($B$11="Todos",$A25,$B$11),BASE_MODELADA!$B$2:$B$462,IF($B$13="Todos","*",$B$13),BASE_MODELADA!$Z$2:$Z$462,1),IF($B$12="Tabaquismo",COUNTIFS(BASE_MODELADA!$A$2:$A$462,"ORIFLAME",BASE_MODELADA!$H$2:$H$462,IF($B$10="Todos","FEMENINO",$B$10),BASE_MODELADA!$I$2:$I$462,IF($B$11="Todos",$A25,$B$11),BASE_MODELADA!$B$2:$B$462,IF($B$13="Todos","*",$B$13),BASE_MODELADA!$W$2:$W$462,1),0))))))))) -> 2 | C25: =IF($B$12="Todos",COUNTIFS(BASE_MODELADA!$A$2:$A$462,"ORIFLAME",BASE_MODELADA!$H$2:$H$462,IF($B$10="Todos","MASCULINO",$B$10),BASE_MODELADA!$I$2:$I$462,IF($B$11="Todos",$A25,$B$11),BASE_MODELADA!$B$2:$B$462,IF($B$13="Todos","*",$B$13),BASE_MODELADA!$AF$2:$AF$462,1),IF($B$12="Diabetes",COUNTIFS(BASE_MODELADA!$A$2:$A$462,"ORIFLAME",BASE_MODELADA!$H$2:$H$462,IF($B$10="Todos","MASCULINO",$B$10),BASE_MODELADA!$I$2:$I$462,IF($B$11="Todos",$A25,$B$11),BASE_MODELADA!$B$2:$B$462,IF($B$13="Todos","*",$B$13),BASE_MODELADA!$K$2:$K$462,1),IF($B$12="Prediabetes",COUNTIFS(BASE_MODELADA!$A$2:$A$462,"ORIFLAME",BASE_MODELADA!$H$2:$H$462,IF($B$10="Todos","MASCULINO",$B$10),BASE_MODELADA!$I$2:$I$462,IF($B$11="Todos",$A25,$B$11),BASE_MODELADA!$B$2:$B$462,IF($B$13="Todos","*",$B$13),BASE_MODELADA!$L$2:$L$462,1),IF($B$12="HTA",COUNTIFS(BASE_MODELADA!$A$2:$A$462,"ORIFLAME",BASE_MODELADA!$H$2:$H$462,IF($B$10="Todos","MASCULINO",$B$10),BASE_MODELADA!$I$2:$I$462,IF($B$11="Todos",$A25,$B$11),BASE_MODELADA!$B$2:$B$462,IF($B$13="Todos","*",$B$13),BASE_MODELADA!$O$2:$O$462,1),IF($B$12="Pre-HTA",COUNTIFS(BASE_MODELADA!$A$2:$A$462,"ORIFLAME",BASE_MODELADA!$H$2:$H$462,IF($B$10="Todos","MASCULINO",$B$10),BASE_MODELADA!$I$2:$I$462,IF($B$11="Todos",$A25,$B$11),BASE_MODELADA!$B$2:$B$462,IF($B$13="Todos","*",$B$13),BASE_MODELADA!$P$2:$P$462,1),IF($B$12="Sobrepeso",COUNTIFS(BASE_MODELADA!$A$2:$A$462,"ORIFLAME",BASE_MODELADA!$H$2:$H$462,IF($B$10="Todos","MASCULINO",$B$10),BASE_MODELADA!$I$2:$I$462,IF($B$11="Todos",$A25,$B$11),BASE_MODELADA!$B$2:$B$462,IF($B$13="Todos","*",$B$13),BASE_MODELADA!$S$2:$S$462,1),IF($B$12="Obesidad",COUNTIFS(BASE_MODELADA!$A$2:$A$462,"ORIFLAME",BASE_MODELADA!$H$2:$H$462,IF($B$10="Todos","MASCULINO",$B$10),BASE_MODELADA!$I$2:$I$462,IF($B$11="Todos",$A25,$B$11),BASE_MODELADA!$B$2:$B$462,IF($B$13="Todos","*",$B$13),BASE_MODELADA!$T$2:$T$462,1),IF($B$12="Dislipidemia",COUNTIFS(BASE_MODELADA!$A$2:$A$462,"ORIFLAME",BASE_MODELADA!$H$2:$H$462,IF($B$10="Todos","MASCULINO",$B$10),BASE_MODELADA!$I$2:$I$462,IF($B$11="Todos",$A25,$B$11),BASE_MODELADA!$B$2:$B$462,IF($B$13="Todos","*",$B$13),BASE_MODELADA!$Z$2:$Z$462,1),IF($B$12="Tabaquismo",COUNTIFS(BASE_MODELADA!$A$2:$A$462,"ORIFLAME",BASE_MODELADA!$H$2:$H$462,IF($B$10="Todos","MASCULINO",$B$10),BASE_MODELADA!$I$2:$I$462,IF($B$11="Todos",$A25,$B$11),BASE_MODELADA!$B$2:$B$462,IF($B$13="Todos","*",$B$13),BASE_MODELADA!$W$2:$W$462,1),0))))))))) -> 1 | D25: =B25+C25 -> 3 | E25: =IFERROR(D25/$D$17,0) -> 0.11111111
A26: 56+ | B26: =IF($B$12="Todos",COUNTIFS(BASE_MODELADA!$A$2:$A$462,"ORIFLAME",BASE_MODELADA!$H$2:$H$462,IF($B$10="Todos","FEMENINO",$B$10),BASE_MODELADA!$I$2:$I$462,IF($B$11="Todos",$A26,$B$11),BASE_MODELADA!$B$2:$B$462,IF($B$13="Todos","*",$B$13),BASE_MODELADA!$AF$2:$AF$462,1),IF($B$12="Diabetes",COUNTIFS(BASE_MODELADA!$A$2:$A$462,"ORIFLAME",BASE_MODELADA!$H$2:$H$462,IF($B$10="Todos","FEMENINO",$B$10),BASE_MODELADA!$I$2:$I$462,IF($B$11="Todos",$A26,$B$11),BASE_MODELADA!$B$2:$B$462,IF($B$13="Todos","*",$B$13),BASE_MODELADA!$K$2:$K$462,1),IF($B$12="Prediabetes",COUNTIFS(BASE_MODELADA!$A$2:$A$462,"ORIFLAME",BASE_MODELADA!$H$2:$H$462,IF($B$10="Todos","FEMENINO",$B$10),BASE_MODELADA!$I$2:$I$462,IF($B$11="Todos",$A26,$B$11),BASE_MODELADA!$B$2:$B$462,IF($B$13="Todos","*",$B$13),BASE_MODELADA!$L$2:$L$462,1),IF($B$12="HTA",COUNTIFS(BASE_MODELADA!$A$2:$A$462,"ORIFLAME",BASE_MODELADA!$H$2:$H$462,IF($B$10="Todos","FEMENINO",$B$10),BASE_MODELADA!$I$2:$I$462,IF($B$11="Todos",$A26,$B$11),BASE_MODELADA!$B$2:$B$462,IF($B$13="Todos","*",$B$13),BASE_MODELADA!$O$2:$O$462,1),IF($B$12="Pre-HTA",COUNTIFS(BASE_MODELADA!$A$2:$A$462,"ORIFLAME",BASE_MODELADA!$H$2:$H$462,IF($B$10="Todos","FEMENINO",$B$10),BASE_MODELADA!$I$2:$I$462,IF($B$11="Todos",$A26,$B$11),BASE_MODELADA!$B$2:$B$462,IF($B$13="Todos","*",$B$13),BASE_MODELADA!$P$2:$P$462,1),IF($B$12="Sobrepeso",COUNTIFS(BASE_MODELADA!$A$2:$A$462,"ORIFLAME",BASE_MODELADA!$H$2:$H$462,IF($B$10="Todos","FEMENINO",$B$10),BASE_MODELADA!$I$2:$I$462,IF($B$11="Todos",$A26,$B$11),BASE_MODELADA!$B$2:$B$462,IF($B$13="Todos","*",$B$13),BASE_MODELADA!$S$2:$S$462,1),IF($B$12="Obesidad",COUNTIFS(BASE_MODELADA!$A$2:$A$462,"ORIFLAME",BASE_MODELADA!$H$2:$H$462,IF($B$10="Todos","FEMENINO",$B$10),BASE_MODELADA!$I$2:$I$462,IF($B$11="Todos",$A26,$B$11),BASE_MODELADA!$B$2:$B$462,IF($B$13="Todos","*",$B$13),BASE_MODELADA!$T$2:$T$462,1),IF($B$12="Dislipidemia",COUNTIFS(BASE_MODELADA!$A$2:$A$462,"ORIFLAME",BASE_MODELADA!$H$2:$H$462,IF($B$10="Todos","FEMENINO",$B$10),BASE_MODELADA!$I$2:$I$462,IF($B$11="Todos",$A26,$B$11),BASE_MODELADA!$B$2:$B$462,IF($B$13="Todos","*",$B$13),BASE_MODELADA!$Z$2:$Z$462,1),IF($B$12="Tabaquismo",COUNTIFS(BASE_MODELADA!$A$2:$A$462,"ORIFLAME",BASE_MODELADA!$H$2:$H$462,IF($B$10="Todos","FEMENINO",$B$10),BASE_MODELADA!$I$2:$I$462,IF($B$11="Todos",$A26,$B$11),BASE_MODELADA!$B$2:$B$462,IF($B$13="Todos","*",$B$13),BASE_MODELADA!$W$2:$W$462,1),0))))))))) -> 0 | C26: =IF($B$12="Todos",COUNTIFS(BASE_MODELADA!$A$2:$A$462,"ORIFLAME",BASE_MODELADA!$H$2:$H$462,IF($B$10="Todos","MASCULINO",$B$10),BASE_MODELADA!$I$2:$I$462,IF($B$11="Todos",$A26,$B$11),BASE_MODELADA!$B$2:$B$462,IF($B$13="Todos","*",$B$13),BASE_MODELADA!$AF$2:$AF$462,1),IF($B$12="Diabetes",COUNTIFS(BASE_MODELADA!$A$2:$A$462,"ORIFLAME",BASE_MODELADA!$H$2:$H$462,IF($B$10="Todos","MASCULINO",$B$10),BASE_MODELADA!$I$2:$I$462,IF($B$11="Todos",$A26,$B$11),BASE_MODELADA!$B$2:$B$462,IF($B$13="Todos","*",$B$13),BASE_MODELADA!$K$2:$K$462,1),IF($B$12="Prediabetes",COUNTIFS(BASE_MODELADA!$A$2:$A$462,"ORIFLAME",BASE_MODELADA!$H$2:$H$462,IF($B$10="Todos","MASCULINO",$B$10),BASE_MODELADA!$I$2:$I$462,IF($B$11="Todos",$A26,$B$11),BASE_MODELADA!$B$2:$B$462,IF($B$13="Todos","*",$B$13),BASE_MODELADA!$L$2:$L$462,1),IF($B$12="HTA",COUNTIFS(BASE_MODELADA!$A$2:$A$462,"ORIFLAME",BASE_MODELADA!$H$2:$H$462,IF($B$10="Todos","MASCULINO",$B$10),BASE_MODELADA!$I$2:$I$462,IF($B$11="Todos",$A26,$B$11),BASE_MODELADA!$B$2:$B$462,IF($B$13="Todos","*",$B$13),BASE_MODELADA!$O$2:$O$462,1),IF($B$12="Pre-HTA",COUNTIFS(BASE_MODELADA!$A$2:$A$462,"ORIFLAME",BASE_MODELADA!$H$2:$H$462,IF($B$10="Todos","MASCULINO",$B$10),BASE_MODELADA!$I$2:$I$462,IF($B$11="Todos",$A26,$B$11),BASE_MODELADA!$B$2:$B$462,IF($B$13="Todos","*",$B$13),BASE_MODELADA!$P$2:$P$462,1),IF($B$12="Sobrepeso",COUNTIFS(BASE_MODELADA!$A$2:$A$462,"ORIFLAME",BASE_MODELADA!$H$2:$H$462,IF($B$10="Todos","MASCULINO",$B$10),BASE_MODELADA!$I$2:$I$462,IF($B$11="Todos",$A26,$B$11),BASE_MODELADA!$B$2:$B$462,IF($B$13="Todos","*",$B$13),BASE_MODELADA!$S$2:$S$462,1),IF($B$12="Obesidad",COUNTIFS(BASE_MODELADA!$A$2:$A$462,"ORIFLAME",BASE_MODELADA!$H$2:$H$462,IF($B$10="Todos","MASCULINO",$B$10),BASE_MODELADA!$I$2:$I$462,IF($B$11="Todos",$A26,$B$11),BASE_MODELADA!$B$2:$B$462,IF($B$13="Todos","*",$B$13),BASE_MODELADA!$T$2:$T$462,1),IF($B$12="Dislipidemia",COUNTIFS(BASE_MODELADA!$A$2:$A$462,"ORIFLAME",BASE_MODELADA!$H$2:$H$462,IF($B$10="Todos","MASCULINO",$B$10),BASE_MODELADA!$I$2:$I$462,IF($B$11="Todos",$A26,$B$11),BASE_MODELADA!$B$2:$B$462,IF($B$13="Todos","*",$B$13),BASE_MODELADA!$Z$2:$Z$462,1),IF($B$12="Tabaquismo",COUNTIFS(BASE_MODELADA!$A$2:$A$462,"ORIFLAME",BASE_MODELADA!$H$2:$H$462,IF($B$10="Todos","MASCULINO",$B$10),BASE_MODELADA!$I$2:$I$462,IF($B$11="Todos",$A26,$B$11),BASE_MODELADA!$B$2:$B$462,IF($B$13="Todos","*",$B$13),BASE_MODELADA!$W$2:$W$462,1),0))))))))) -> 1 | D26: =B26+C26 -> 1 | E26: =IFERROR(D26/$D$17,0) -> 0.037037037
A28: Distribución IMC (según filtros)
A29: Categoría | B29: N | C29: %
A30: Normopeso | B30: =COUNTIFS(BASE_MODELADA!$A$2:$A$462,"ORIFLAME",BASE_MODELADA!$H$2:$H$462,IF($B$10="Todos","*",$B$10),BASE_MODELADA!$I$2:$I$462,IF($B$11="Todos","*",$B$11),BASE_MODELADA!$B$2:$B$462,IF($B$13="Todos","*",$B$13),BASE_MODELADA!$U$2:$U$462,1,BASE_MODELADA!$R$2:$R$462,"NORMOPESO") -> 10 | C30: =IFERROR(B30/SUM($B$30:$B$32),0) -> 0.37037037
A31: Sobrepeso | B31: =COUNTIFS(BASE_MODELADA!$A$2:$A$462,"ORIFLAME",BASE_MODELADA!$H$2:$H$462,IF($B$10="Todos","*",$B$10),BASE_MODELADA!$I$2:$I$462,IF($B$11="Todos","*",$B$11),BASE_MODELADA!$B$2:$B$462,IF($B$13="Todos","*",$B$13),BASE_MODELADA!$U$2:$U$462,1,BASE_MODELADA!$R$2:$R$462,"SOBREPESO") -> 13 | C31: =IFERROR(B31/SUM($B$30:$B$32),0) -> 0.48148148
A32: Obesidad | B32: =COUNTIFS(BASE_MODELADA!$A$2:$A$462,"ORIFLAME",BASE_MODELADA!$H$2:$H$462,IF($B$10="Todos","*",$B$10),BASE_MODELADA!$I$2:$I$462,IF($B$11="Todos","*",$B$11),BASE_MODELADA!$B$2:$B$462,IF($B$13="Todos","*",$B$13),BASE_MODELADA!$U$2:$U$462,1,BASE_MODELADA!$R$2:$R$462,"OBESIDAD") -> 4 | C32: =IFERROR(B32/SUM($B$30:$B$32),0) -> 0.14814815
A34: Dislipidemia (según filtros)
A35: Estado | B35: N | C35: %
A36: SI | B36: =COUNTIFS(BASE_MODELADA!$A$2:$A$462,"ORIFLAME",BASE_MODELADA!$H$2:$H$462,IF($B$10="Todos","*",$B$10),BASE_MODELADA!$I$2:$I$462,IF($B$11="Todos","*",$B$11),BASE_MODELADA!$B$2:$B$462,IF($B$13="Todos","*",$B$13),BASE_MODELADA!$AA$2:$AA$462,1,BASE_MODELADA!$Y$2:$Y$462,"SI") -> 12 | C36: =IFERROR(B36/SUM($B$36:$B$38),0) -> 0.44444444
A37: NO | B37: =COUNTIFS(BASE_MODELADA!$A$2:$A$462,"ORIFLAME",BASE_MODELADA!$H$2:$H$462,IF($B$10="Todos","*",$B$10),BASE_MODELADA!$I$2:$I$462,IF($B$11="Todos","*",$B$11),BASE_MODELADA!$B$2:$B$462,IF($B$13="Todos","*",$B$13),BASE_MODELADA!$AA$2:$AA$462,1,BASE_MODELADA!$Y$2:$Y$462,"NO") -> 15 | C37: =IFERROR(B37/SUM($B$36:$B$38),0) -> 0.55555556
A38: NA | B38: =COUNTIFS(BASE_MODELADA!$A$2:$A$462,"ORIFLAME",BASE_MODELADA!$H$2:$H$462,IF($B$10="Todos","*",$B$10),BASE_MODELADA!$I$2:$I$462,IF($B$11="Todos","*",$B$11),BASE_MODELADA!$B$2:$B$462,IF($B$13="Todos","*",$B$13),BASE_MODELADA!$AA$2:$AA$462,1,BASE_MODELADA!$Y$2:$Y$462,"NA") -> 0 | C38: =IFERROR(B38/SUM($B$36:$B$38),0) -> 0

Sheet KIO
A1: Reporte Vitalbit Ejecutivo Pro — KIO | 2026-01-08
A2: HALLAZGOS CLAVE: • Dashboard interactivo con filtros por sexo, edad, condición, jornada y población (KIO). • Prediabetes incluye GAA y glucosa 100–125 mg/dL; Diabetes ≥126 mg/dL o 'DM'. • HTA y Pre-HTA se reportan por separado (no se mezclan). • Sobrepeso y Obesidad se reportan por separado. • Dislipidemia: se usa columna explícita si existe; si falta, regla >200 (CT/J-O según disponibilidad).
A9: FILTROS (Interactivo)
A10: Sexo | B10: Todos | D10: Tip: cambia filtros y el dashboard se actualiza.
A11: Rango de Edad | B11: Todos
A12: Población (IT vs Data Centers) | B12: Todos
A13: Condición | B13: Diabetes
A14: Nota: Los KPIs y porcentajes se calculan exclusivamente sobre la 'Muestra aplicable' (registros con información clínica completa según el set de variables requerido por cada indicador). | K14: ⓘ BASE KPI
A15: RESUMEN (KPIs)
A16: Total RAW (registros) | D16: Muestra aplicable | G16: Casos (según condición) | I16: % sobre muestra
A17: =COUNTIFS(BASE_MODELADA!$A$2:$A$462,"KIO",BASE_MODELADA!$H$2:$H$462,IF($B$10="Todos","*",$B$10),BASE_MODELADA!$I$2:$I$462,IF($B$11="Todos","*",$B$11),BASE_MODELADA!$D$2:$D$462,IF($B$12="Todos","*",$B$12)) -> 395 | D17: =IF($B$13="Todos",COUNTIFS(BASE_MODELADA!$A$2:$A$462,"KIO",BASE_MODELADA!$H$2:$H$462,IF($B$10="Todos","*",$B$10),BASE_MODELADA!$I$2:$I$462,IF($B$11="Todos","*",$B$11),BASE_MODELADA!$D$2:$D$462,IF($B$12="Todos","*",$B$12),BASE_MODELADA!$AF$2:$AF$462,1),IF(OR($B$13="Diabetes",$B$13="Prediabetes"),COUNTIFS(BASE_MODELADA!$A$2:$A$462,"KIO",BASE_MODELADA!$H$2:$H$462,IF($B$10="Todos","*",$B$10),BASE_MODELADA!$I$2:$I$462,IF($B$11="Todos","*",$B$11),BASE_MODELADA!$D$2:$D$462,IF($B$12="Todos","*",$B$12),BASE_MODELADA!$M$2:$M$462,1),IF(OR($B$13="HTA",$B$13="Pre-HTA"),COUNTIFS(BASE_MODELADA!$A$2:$A$462,"KIO",BASE_MODELADA!$H$2:$H$462,IF($B$10="Todos","*",$B$10),BASE_MODELADA!$I$2:$I$462,IF($B$11="Todos","*",$B$11),BASE_MODELADA!$D$2:$D$462,IF($B$12="Todos","*",$B$12),BASE_MODELADA!$Q$2:$Q$462,1),IF(OR($B$13="Sobrepeso",$B$13="Obesidad"),COUNTIFS(BASE_MODELADA!$A$2:$A$462,"KIO",BASE_MODELADA!$H$2:$H$462,IF($B$10="Todos","*",$B$10),BASE_MODELADA!$I$2:$I$462,IF($B$11="Todos","*",$B$11),BASE_MODELADA!$D$2:$D$462,IF($B$12="Todos","*",$B$12),BASE_MODELADA!$U$2:$U$462,1),IF($B$13="Dislipidemia",COUNTIFS(BASE_MODELADA!$A$2:$A$462,"KIO",BASE_MODELADA!$H$2:$H$462,IF($B$10="Todos","*",$B$10),BASE_MODELADA!$I$2:$I$462,IF($B$11="Todos","*",$B$11),BASE_MODELADA!$D$2:$D$462,IF($B$12="Todos","*",$B$12),BASE_MODELADA!$AA$2:$AA$462,1),IF($B$13="Tabaquismo",COUNTIFS(BASE_MODELADA!$A$2:$A$462,"KIO",BASE_MODELADA!$H$2:$H$462,IF($B$10="Todos","*",$B$10),BASE_MODELADA!$I$2:$I$462,IF($B$11="Todos","*",$B$11),BASE_MODELADA!$D$2:$D$462,IF($B$12="Todos","*",$B$12),BASE_MODELADA!$X$2:$X$462,1),0)))))) -> 393 | G17: =IF($B$13="Diabetes",COUNTIFS(BASE_MODELADA!$A$2:$A$462,"KIO",BASE_MODELADA!$H$2:$H$462,IF($B$10="Todos","*",$B$10),BASE_MODELADA!$I$2:$I$462,IF($B$11="Todos","*",$B$11),BASE_MODELADA!$D$2:$D$462,IF($B$12="Todos","*",$B$12),BASE_MODELADA!$K$2:$K$462,1),IF($B$13="Prediabetes",COUNTIFS(BASE_MODELADA!$A$2:$A$462,"KIO",BASE_MODELADA!$H$2:$H$462,IF($B$10="Todos","*",$B$10),BASE_MODELADA!$I$2:$I$462,IF($B$11="Todos","*",$B$11),BASE_MODELADA!$D$2:$D$462,IF($B$12="Todos","*",$B$12),BASE_MODELADA!$L$2:$L$462,1),IF($B$13="HTA",COUNTIFS(BASE_MODELADA!$A$2:$A$462,"KIO",BASE_MODELADA!$H$2:$H$462,IF($B$10="Todos","*",$B$10),BASE_MODELADA!$I$2:$I$462,IF($B$11="Todos","*",$B$11),BASE_MODELADA!$D$2:$D$462,IF($B$12="Todos","*",$B$12),BASE_MODELADA!$O$2:$O$462,1),IF($B$13="Pre-HTA",COUNTIFS(BASE_MODELADA!$A$2:$A$462,"KIO",BASE_MODELADA!$H$2:$H$462,IF($B$10="Todos","*",$B$10),BASE_MODELADA!$I$2:$I$462,IF($B$11="Todos","*",$B$11),BASE_MODELADA!$D$2:$D$462,IF($B$12="Todos","*",$B$12),BASE_MODELADA!$P$2:$P$462,1),IF($B$13="Sobrepeso",COUNTIFS(BASE_MODELADA!$A$2:$A$462,"KIO",BASE_MODELADA!$H$2:$H$462,IF($B$10="Todos","*",$B$10),BASE_MODELADA!$I$2:$I$462,IF($B$11="Todos","*",$B$11),BASE_MODELADA!$D$2:$D$462,IF($B$12="Todos","*",$B$12),BASE_MODELADA!$S$2:$S$462,1),IF($B$13="Obesidad",COUNTIFS(BASE_MODELADA!$A$2:$A$462,"KIO",BASE_MODELADA!$H$2:$H$462,IF($B$10="Todos","*",$B$10),BASE_MODELADA!$I$2:$I$462,IF($B$11="Todos","*",$B$11),BASE_MODELADA!$D$2:$D$462,IF($B$12="Todos","*",$B$12),BASE_MODELADA!$T$2:$T$462,1),IF($B$13="Dislipidemia",COUNTIFS(BASE_MODELADA!$A$2:$A$462,"KIO",BASE_MODELADA!$H$2:$H$462,IF($B$10="Todos","*",$B$10),BASE_MODELADA!$I$2:$I$462,IF($B$11="Todos","*",$B$11),BASE_MODELADA!$D$2:$D$462,IF($B$12="Todos","*",$B$12),BASE_MODELADA!$Z$2:$Z$462,1),IF($B$13="Tabaquismo",COUNTIFS(BASE_MODELADA!$A$2:$A$462,"KIO",BASE_MODELADA!$H$2:$H$462,IF($B$10="Todos","*",$B$10),BASE_MODELADA!$I$2:$I$462,IF($B$11="Todos","*",$B$11),BASE_MODELADA!$D$2:$D$462,IF($B$12="Todos","*",$B$12),BASE_MODELADA!$W$2:$W$462,1),0)))))))) -> 23 | I17: =IFERROR($G$17/$D$17,0) -> 0.058524173
A20: Distribución Edad x Género (condición seleccionada)
A21: Rango Edad | B21: Femenino | C21: Masculino | D21: Total | E21: %
